<?xml version="1.0" ?>
<robot name="articulated_object">
  <!-- Auto-generated from object.json -->
  <!-- Conversion script: convert_object_json_to_urdf.py -->
  <!-- Formula: mesh_origin = -joint_origin (for main parts) -->
  <!--          mesh_origin = -parent_joint_origin (for fixed children) -->
  <link name="drawer">
    <visual>
      <origin xyz="-0.352616 -0.503853 -0.208335" rpy="0 0 0"/>
      <geometry>
        <mesh filename="objs/2c681d7e64e0410d76156f500cd2df798975a25d_part_1.obj"/>
      </geometry>
    </visual>
    <collision>
      <origin xyz="-0.352616 -0.503853 -0.208335" rpy="0 0 0"/>
      <geometry>
        <mesh filename="objs/2c681d7e64e0410d76156f500cd2df798975a25d_part_1.obj"/>
      </geometry>
    </collision>
    <inertial>
      <origin xyz="-0.352616 -0.503853 -0.208335" rpy="0 0 0"/>
      <mass value="3.0"/>
      <inertia ixx="0.03" ixy="0" ixz="0" iyy="0.03" iyz="0" izz="0.03"/>
    </inertial>
  </link>
  <joint name="joint_drawer" type="prismatic">
    <parent link="base_link"/>
    <child link="drawer"/>
    <origin xyz="0.352616 0.503853 0.208335" rpy="0 0 0"/>
    <axis xyz="-1e-06 0.0 1.0"/>
    <limit lower="0.0" upper="0.2396457947170301" effort="10" velocity="1"/>
  </joint>
  <link name="drawer_1">
    <visual>
      <origin xyz="0.353037 -0.503853 -0.208334" rpy="0 0 0"/>
      <geometry>
        <mesh filename="objs/2c681d7e64e0410d76156f500cd2df798975a25d_part_2.obj"/>
      </geometry>
    </visual>
    <collision>
      <origin xyz="0.353037 -0.503853 -0.208334" rpy="0 0 0"/>
      <geometry>
        <mesh filename="objs/2c681d7e64e0410d76156f500cd2df798975a25d_part_2.obj"/>
      </geometry>
    </collision>
    <inertial>
      <origin xyz="0.353037 -0.503853 -0.208334" rpy="0 0 0"/>
      <mass value="3.0"/>
      <inertia ixx="0.03" ixy="0" ixz="0" iyy="0.03" iyz="0" izz="0.03"/>
    </inertial>
  </link>
  <joint name="joint_drawer_1" type="prismatic">
    <parent link="base_link"/>
    <child link="drawer_1"/>
    <origin xyz="-0.353037 0.503853 0.208334" rpy="0 0 0"/>
    <axis xyz="-1e-06 0.0 1.0"/>
    <limit lower="0.0" upper="0.2396454806736347" effort="10" velocity="1"/>
  </joint>
  <link name="knob">
    <visual>
      <origin xyz="-0.352616 -0.503853 -0.208335" rpy="0 0 0"/>
      <geometry>
        <mesh filename="objs/2c681d7e64e0410d76156f500cd2df798975a25d_part_3.obj"/>
      </geometry>
    </visual>
    <collision>
      <origin xyz="-0.352616 -0.503853 -0.208335" rpy="0 0 0"/>
      <geometry>
        <mesh filename="objs/2c681d7e64e0410d76156f500cd2df798975a25d_part_3.obj"/>
      </geometry>
    </collision>
    <inertial>
      <origin xyz="-0.352616 -0.503853 -0.208335" rpy="0 0 0"/>
      <mass value="0.1"/>
      <inertia ixx="0.001" ixy="0" ixz="0" iyy="0.001" iyz="0" izz="0.001"/>
    </inertial>
  </link>
  <joint name="joint_knob" type="fixed">
    <parent link="drawer"/>
    <child link="knob"/>
    <origin xyz="0.000000 0.000000 0.000000" rpy="0 0 0"/>
  </joint>
  <link name="knob_1">
    <visual>
      <origin xyz="0.353037 -0.503853 -0.208334" rpy="0 0 0"/>
      <geometry>
        <mesh filename="objs/2c681d7e64e0410d76156f500cd2df798975a25d_part_4.obj"/>
      </geometry>
    </visual>
    <collision>
      <origin xyz="0.353037 -0.503853 -0.208334" rpy="0 0 0"/>
      <geometry>
        <mesh filename="objs/2c681d7e64e0410d76156f500cd2df798975a25d_part_4.obj"/>
      </geometry>
    </collision>
    <inertial>
      <origin xyz="0.353037 -0.503853 -0.208334" rpy="0 0 0"/>
      <mass value="0.1"/>
      <inertia ixx="0.001" ixy="0" ixz="0" iyy="0.001" iyz="0" izz="0.001"/>
    </inertial>
  </link>
  <joint name="joint_knob_1" type="fixed">
    <parent link="drawer_1"/>
    <child link="knob_1"/>
    <origin xyz="0.000000 0.000000 0.000000" rpy="0 0 0"/>
  </joint>
  <link name="base_link">
    <visual>
      <origin xyz="-0.000000 -0.000000 -0.000000" rpy="0 0 0"/>
      <geometry>
        <mesh filename="objs/2c681d7e64e0410d76156f500cd2df798975a25d_part_5.obj"/>
      </geometry>
    </visual>
    <collision>
      <origin xyz="-0.000000 -0.000000 -0.000000" rpy="0 0 0"/>
      <geometry>
        <mesh filename="objs/2c681d7e64e0410d76156f500cd2df798975a25d_part_5.obj"/>
      </geometry>
    </collision>
    <inertial>
      <origin xyz="-0.000000 -0.000000 -0.000000" rpy="0 0 0"/>
      <mass value="10.0"/>
      <inertia ixx="0.1" ixy="0" ixz="0" iyy="0.1" iyz="0" izz="0.1"/>
    </inertial>
  </link>
</robot>