<?xml version='1.0' encoding='UTF-8'?>
<mujoco model="articulated_object">
  <compiler angle="radian"/>
  <asset>
    <mesh name="new-2" content_type="model/obj" file="objs/new-2.obj"/>
    <mesh name="original-16" content_type="model/obj" file="objs/original-16.obj"/>
    <mesh name="new-0" content_type="model/obj" file="objs/new-0.obj"/>
    <mesh name="new-3" content_type="model/obj" file="objs/new-3.obj"/>
    <mesh name="original-3" content_type="model/obj" file="objs/original-3.obj"/>
    <mesh name="original-9" content_type="model/obj" file="objs/original-9.obj"/>
    <mesh name="original-17" content_type="model/obj" file="objs/original-17.obj"/>
    <mesh name="original-14" content_type="model/obj" file="objs/original-14.obj"/>
    <mesh name="original-15" content_type="model/obj" file="objs/original-15.obj"/>
    <mesh name="original-8" content_type="model/obj" file="objs/original-8.obj"/>
    <mesh name="original-7" content_type="model/obj" file="objs/original-7.obj"/>
    <mesh name="original-6" content_type="model/obj" file="objs/original-6.obj"/>
    <mesh name="original-5" content_type="model/obj" file="objs/original-5.obj"/>
    <mesh name="original-1" content_type="model/obj" file="objs/original-1.obj"/>
    <mesh name="original-18" content_type="model/obj" file="objs/original-18.obj"/>
    <mesh name="original-10" content_type="model/obj" file="objs/original-10.obj"/>
    <mesh name="original-13" content_type="model/obj" file="objs/original-13.obj"/>
    <mesh name="original-12" content_type="model/obj" file="objs/original-12.obj"/>
    <mesh name="original-11" content_type="model/obj" file="objs/original-11.obj"/>
  </asset>
  <worldbody>
    <body name="base">
      <inertial pos="0 0 0" mass="0.1" diaginertia="0.001 0.001 0.001"/>
      <geom type="mesh" mesh="new-0"/>
      <geom type="mesh" mesh="new-3"/>
      <geom type="mesh" mesh="original-3"/>
      <body name="door" pos="0.508704 -0.53191 0.44953">
        <inertial pos="-0.508704 0.53191 -0.44953" mass="2" diaginertia="0.02 0.02 0.02"/>
        <joint name="joint_door" pos="0 0 0" axis="1 0 0" range="0 1.5708" actuatorfrcrange="-10 10"/>
        <geom pos="-0.508704 0.53191 -0.44953" quat="1 0 0 0" type="mesh" mesh="new-2"/>
        <geom pos="-0.508704 0.53191 -0.44953" quat="1 0 0 0" type="mesh" mesh="original-16"/>
        <body name="base_link">
          <inertial pos="-0.508704 0.53191 -0.44953" mass="10" diaginertia="0.1 0.1 0.1"/>
          <geom pos="-0.508704 0.53191 -0.44953" quat="1 0 0 0" type="mesh" mesh="original-9"/>
          <geom pos="-0.508704 0.53191 -0.44953" type="mesh" mesh="original-17"/>
          <geom pos="-0.508704 0.53191 -0.44953" type="mesh" mesh="original-14"/>
          <geom pos="-0.508704 0.53191 -0.44953" type="mesh" mesh="original-15"/>
          <geom pos="-0.508704 0.53191 -0.44953" quat="1 0 0 0" type="mesh" mesh="original-8"/>
          <geom pos="-0.508704 0.53191 -0.44953" quat="1 0 0 0" type="mesh" mesh="original-7"/>
          <geom pos="-0.508704 0.53191 -0.44953" quat="1 0 0 0" type="mesh" mesh="original-6"/>
          <geom pos="-0.508704 0.53191 -0.44953" quat="1 0 0 0" type="mesh" mesh="original-5"/>
          <geom pos="-0.508704 0.53191 -0.44953" quat="1 0 0 0" type="mesh" mesh="original-1"/>
          <geom pos="-0.508704 0.53191 -0.44953" type="mesh" mesh="original-18"/>
          <geom pos="-0.508704 0.53191 -0.44953" type="mesh" mesh="original-10"/>
          <geom pos="-0.508704 0.53191 -0.44953" type="mesh" mesh="original-13"/>
          <geom pos="-0.508704 0.53191 -0.44953" type="mesh" mesh="original-12"/>
          <geom pos="-0.508704 0.53191 -0.44953" type="mesh" mesh="original-11"/>
        </body>
      </body>
    </body>
  </worldbody>
</mujoco>
