<?xml version="1.0" ?>
<robot name="articulated_object">
  <!-- Auto-generated from object.json -->
  <!-- Conversion script: convert_object_json_to_urdf.py -->
  <!-- Formula: mesh_origin = -joint_origin (for main parts) -->
  <!--          mesh_origin = -parent_joint_origin (for fixed children) -->
  <link name="door">
    <visual>
      <origin xyz="-0.508704 0.531910 -0.449530" rpy="0 0 0"/>
      <geometry>
        <mesh filename="objs/new-2.obj"/>
      </geometry>
    </visual>
    <collision>
      <origin xyz="-0.508704 0.531910 -0.449530" rpy="0 0 0"/>
      <geometry>
        <mesh filename="objs/new-2.obj"/>
      </geometry>
    </collision>
    <visual>
      <origin xyz="-0.508704 0.531910 -0.449530" rpy="0 0 0"/>
      <geometry>
        <mesh filename="objs/original-16.obj"/>
      </geometry>
    </visual>
    <collision>
      <origin xyz="-0.508704 0.531910 -0.449530" rpy="0 0 0"/>
      <geometry>
        <mesh filename="objs/original-16.obj"/>
      </geometry>
    </collision>
    <inertial>
      <origin xyz="-0.508704 0.531910 -0.449530" rpy="0 0 0"/>
      <mass value="2.0"/>
      <inertia ixx="0.02" ixy="0" ixz="0" iyy="0.02" iyz="0" izz="0.02"/>
    </inertial>
  </link>
  <joint name="joint_door" type="revolute">
    <parent link="base"/>
    <child link="door"/>
    <origin xyz="0.508704 -0.531910 0.449530" rpy="0 0 0"/>
    <axis xyz="1 0 0"/>
    <limit lower="0.000000" upper="1.570796" effort="10" velocity="1"/>
  </joint>
  <link name="base">
    <visual>
      <origin xyz="0.000000 0.000000 0.000000" rpy="0 0 0"/>
      <geometry>
        <mesh filename="objs/new-0.obj"/>
      </geometry>
    </visual>
    <collision>
      <origin xyz="0.000000 0.000000 0.000000" rpy="0 0 0"/>
      <geometry>
        <mesh filename="objs/new-0.obj"/>
      </geometry>
    </collision>
    <visual>
      <origin xyz="0.000000 0.000000 0.000000" rpy="0 0 0"/>
      <geometry>
        <mesh filename="objs/new-3.obj"/>
      </geometry>
    </visual>
    <collision>
      <origin xyz="0.000000 0.000000 0.000000" rpy="0 0 0"/>
      <geometry>
        <mesh filename="objs/new-3.obj"/>
      </geometry>
    </collision>
    <visual>
      <origin xyz="0.000000 0.000000 0.000000" rpy="0 0 0"/>
      <geometry>
        <mesh filename="objs/original-3.obj"/>
      </geometry>
    </visual>
    <collision>
      <origin xyz="0.000000 0.000000 0.000000" rpy="0 0 0"/>
      <geometry>
        <mesh filename="objs/original-3.obj"/>
      </geometry>
    </collision>
    <inertial>
      <origin xyz="0.000000 0.000000 0.000000" rpy="0 0 0"/>
      <mass value="0.1"/>
      <inertia ixx="0.001" ixy="0" ixz="0" iyy="0.001" iyz="0" izz="0.001"/>
    </inertial>
  </link>
  <link name="base_link">
    <visual>
      <origin xyz="-0.508704 0.531910 -0.449530" rpy="0 0 0"/>
      <geometry>
        <mesh filename="objs/original-9.obj"/>
      </geometry>
    </visual>
    <collision>
      <origin xyz="-0.508704 0.531910 -0.449530" rpy="0 0 0"/>
      <geometry>
        <mesh filename="objs/original-9.obj"/>
      </geometry>
    </collision>
    <visual>
      <origin xyz="-0.508704 0.531910 -0.449530" rpy="0 0 0"/>
      <geometry>
        <mesh filename="objs/original-17.obj"/>
      </geometry>
    </visual>
    <collision>
      <origin xyz="-0.508704 0.531910 -0.449530" rpy="0 0 0"/>
      <geometry>
        <mesh filename="objs/original-17.obj"/>
      </geometry>
    </collision>
    <visual>
      <origin xyz="-0.508704 0.531910 -0.449530" rpy="0 0 0"/>
      <geometry>
        <mesh filename="objs/original-14.obj"/>
      </geometry>
    </visual>
    <collision>
      <origin xyz="-0.508704 0.531910 -0.449530" rpy="0 0 0"/>
      <geometry>
        <mesh filename="objs/original-14.obj"/>
      </geometry>
    </collision>
    <visual>
      <origin xyz="-0.508704 0.531910 -0.449530" rpy="0 0 0"/>
      <geometry>
        <mesh filename="objs/original-15.obj"/>
      </geometry>
    </visual>
    <collision>
      <origin xyz="-0.508704 0.531910 -0.449530" rpy="0 0 0"/>
      <geometry>
        <mesh filename="objs/original-15.obj"/>
      </geometry>
    </collision>
    <visual>
      <origin xyz="-0.508704 0.531910 -0.449530" rpy="0 0 0"/>
      <geometry>
        <mesh filename="objs/original-8.obj"/>
      </geometry>
    </visual>
    <collision>
      <origin xyz="-0.508704 0.531910 -0.449530" rpy="0 0 0"/>
      <geometry>
        <mesh filename="objs/original-8.obj"/>
      </geometry>
    </collision>
    <visual>
      <origin xyz="-0.508704 0.531910 -0.449530" rpy="0 0 0"/>
      <geometry>
        <mesh filename="objs/original-7.obj"/>
      </geometry>
    </visual>
    <collision>
      <origin xyz="-0.508704 0.531910 -0.449530" rpy="0 0 0"/>
      <geometry>
        <mesh filename="objs/original-7.obj"/>
      </geometry>
    </collision>
    <visual>
      <origin xyz="-0.508704 0.531910 -0.449530" rpy="0 0 0"/>
      <geometry>
        <mesh filename="objs/original-6.obj"/>
      </geometry>
    </visual>
    <collision>
      <origin xyz="-0.508704 0.531910 -0.449530" rpy="0 0 0"/>
      <geometry>
        <mesh filename="objs/original-6.obj"/>
      </geometry>
    </collision>
    <visual>
      <origin xyz="-0.508704 0.531910 -0.449530" rpy="0 0 0"/>
      <geometry>
        <mesh filename="objs/original-5.obj"/>
      </geometry>
    </visual>
    <collision>
      <origin xyz="-0.508704 0.531910 -0.449530" rpy="0 0 0"/>
      <geometry>
        <mesh filename="objs/original-5.obj"/>
      </geometry>
    </collision>
    <visual>
      <origin xyz="-0.508704 0.531910 -0.449530" rpy="0 0 0"/>
      <geometry>
        <mesh filename="objs/original-1.obj"/>
      </geometry>
    </visual>
    <collision>
      <origin xyz="-0.508704 0.531910 -0.449530" rpy="0 0 0"/>
      <geometry>
        <mesh filename="objs/original-1.obj"/>
      </geometry>
    </collision>
    <visual>
      <origin xyz="-0.508704 0.531910 -0.449530" rpy="0 0 0"/>
      <geometry>
        <mesh filename="objs/original-18.obj"/>
      </geometry>
    </visual>
    <collision>
      <origin xyz="-0.508704 0.531910 -0.449530" rpy="0 0 0"/>
      <geometry>
        <mesh filename="objs/original-18.obj"/>
      </geometry>
    </collision>
    <visual>
      <origin xyz="-0.508704 0.531910 -0.449530" rpy="0 0 0"/>
      <geometry>
        <mesh filename="objs/original-10.obj"/>
      </geometry>
    </visual>
    <collision>
      <origin xyz="-0.508704 0.531910 -0.449530" rpy="0 0 0"/>
      <geometry>
        <mesh filename="objs/original-10.obj"/>
      </geometry>
    </collision>
    <visual>
      <origin xyz="-0.508704 0.531910 -0.449530" rpy="0 0 0"/>
      <geometry>
        <mesh filename="objs/original-13.obj"/>
      </geometry>
    </visual>
    <collision>
      <origin xyz="-0.508704 0.531910 -0.449530" rpy="0 0 0"/>
      <geometry>
        <mesh filename="objs/original-13.obj"/>
      </geometry>
    </collision>
    <visual>
      <origin xyz="-0.508704 0.531910 -0.449530" rpy="0 0 0"/>
      <geometry>
        <mesh filename="objs/original-12.obj"/>
      </geometry>
    </visual>
    <collision>
      <origin xyz="-0.508704 0.531910 -0.449530" rpy="0 0 0"/>
      <geometry>
        <mesh filename="objs/original-12.obj"/>
      </geometry>
    </collision>
    <visual>
      <origin xyz="-0.508704 0.531910 -0.449530" rpy="0 0 0"/>
      <geometry>
        <mesh filename="objs/original-11.obj"/>
      </geometry>
    </visual>
    <collision>
      <origin xyz="-0.508704 0.531910 -0.449530" rpy="0 0 0"/>
      <geometry>
        <mesh filename="objs/original-11.obj"/>
      </geometry>
    </collision>
    <inertial>
      <origin xyz="-0.508704 0.531910 -0.449530" rpy="0 0 0"/>
      <mass value="10.0"/>
      <inertia ixx="0.1" ixy="0" ixz="0" iyy="0.1" iyz="0" izz="0.1"/>
    </inertial>
  </link>
  <joint name="joint_base_link" type="fixed">
    <parent link="door"/>
    <child link="base_link"/>
    <origin xyz="0 0 0" rpy="0 0 0"/>
  </joint>
</robot>